Exception in thread Thread-8:
Traceback (most recent call last):
  File "/home/jeffreymo572/anaconda3/envs/Kaggles/lib/python3.8/threading.py", line 932, in _bootstrap_inner
    self.run()
  File "/home/jeffreymo572/anaconda3/envs/Kaggles/lib/python3.8/threading.py", line 870, in run
    self._target(*self._args, **self._kwargs)
  File "/home/jeffreymo572/anaconda3/envs/Kaggles/lib/python3.8/site-packages/torch/utils/data/_utils/pin_memory.py", line 49, in _pin_memory_loop
    do_one_step()
  File "/home/jeffreymo572/anaconda3/envs/Kaggles/lib/python3.8/site-packages/torch/utils/data/_utils/pin_memory.py", line 26, in do_one_step
    r = in_queue.get(timeout=MP_STATUS_CHECK_INTERVAL)
  File "/home/jeffreymo572/anaconda3/envs/Kaggles/lib/python3.8/multiprocessing/queues.py", line 116, in get
    return _ForkingPickler.loads(res)
  File "/home/jeffreymo572/anaconda3/envs/Kaggles/lib/python3.8/site-packages/torch/multiprocessing/reductions.py", line 305, in rebuild_storage_fd
    fd = df.detach()
  File "/home/jeffreymo572/anaconda3/envs/Kaggles/lib/python3.8/multiprocessing/resource_sharer.py", line 57, in detach
    with _resource_sharer.get_connection(self._id) as conn:
  File "/home/jeffreymo572/anaconda3/envs/Kaggles/lib/python3.8/multiprocessing/resource_sharer.py", line 87, in get_connection
    c = Client(address, authkey=process.current_process().authkey)
  File "/home/jeffreymo572/anaconda3/envs/Kaggles/lib/python3.8/multiprocessing/connection.py", line 508, in Client
    answer_challenge(c, authkey)
  File "/home/jeffreymo572/anaconda3/envs/Kaggles/lib/python3.8/multiprocessing/connection.py", line 757, in answer_challenge
    response = connection.recv_bytes(256)        # reject large message
  File "/home/jeffreymo572/anaconda3/envs/Kaggles/lib/python3.8/multiprocessing/connection.py", line 216, in recv_bytes
    buf = self._recv_bytes(maxlength)
  File "/home/jeffreymo572/anaconda3/envs/Kaggles/lib/python3.8/multiprocessing/connection.py", line 414, in _recv_bytes
    buf = self._recv(4)
  File "/home/jeffreymo572/anaconda3/envs/Kaggles/lib/python3.8/multiprocessing/connection.py", line 379, in _recv
    chunk = read(handle, remaining)
ConnectionResetError: [Errno 104] Connection reset by peer
Traceback (most recent call last):
  File "main.py", line 47, in <module>
    history = fit(epochs, net, train_ds, val_ds, device, opt = optimizer)
  File "/home/jeffreymo572/Kaggles/common/utils.py", line 124, in fit
    losses.append(loss.cpu().detach().numpy())
KeyboardInterrupt