Exception in thread Thread-64:
Traceback (most recent call last):
  File "/home/jeffreymo572/anaconda3/envs/Kaggles/lib/python3.8/threading.py", line 932, in _bootstrap_inner
    self.run()
  File "/home/jeffreymo572/anaconda3/envs/Kaggles/lib/python3.8/threading.py", line 870, in run
    self._target(*self._args, **self._kwargs)
  File "/home/jeffreymo572/anaconda3/envs/Kaggles/lib/python3.8/site-packages/torch/utils/data/_utils/pin_memory.py", line 49, in _pin_memory_loop
    do_one_step()
  File "/home/jeffreymo572/anaconda3/envs/Kaggles/lib/python3.8/site-packages/torch/utils/data/_utils/pin_memory.py", line 26, in do_one_step
    r = in_queue.get(timeout=MP_STATUS_CHECK_INTERVAL)
  File "/home/jeffreymo572/anaconda3/envs/Kaggles/lib/python3.8/multiprocessing/queues.py", line 116, in get
    return _ForkingPickler.loads(res)
  File "/home/jeffreymo572/anaconda3/envs/Kaggles/lib/python3.8/site-packages/torch/multiprocessing/reductions.py", line 305, in rebuild_storage_fd
    fd = df.detach()
  File "/home/jeffreymo572/anaconda3/envs/Kaggles/lib/python3.8/multiprocessing/resource_sharer.py", line 57, in detach
    with _resource_sharer.get_connection(self._id) as conn:
  File "/home/jeffreymo572/anaconda3/envs/Kaggles/lib/python3.8/multiprocessing/resource_sharer.py", line 87, in get_connection
    c = Client(address, authkey=process.current_process().authkey)
  File "/home/jeffreymo572/anaconda3/envs/Kaggles/lib/python3.8/multiprocessing/connection.py", line 502, in Client
    c = SocketClient(address)
  File "/home/jeffreymo572/anaconda3/envs/Kaggles/lib/python3.8/multiprocessing/connection.py", line 630, in SocketClient
    s.connect(address)
FileNotFoundError: [Errno 2] No such file or directory
Traceback (most recent call last):
  File "main.py", line 48, in <module>
    history = fit(epochs, net, train_ds, val_ds, device, opt = optimizer)
  File "/home/jeffreymo572/Kaggles/common/utils.py", line 122, in fit
    losses.append(loss.cpu().detach().numpy())
KeyboardInterrupt