Traceback (most recent call last):
  File "main.py", line 47, in <module>
    history = fit(epochs, net, train_ds, val_ds, device, opt = optimizer)
  File "/home/jeffreymo572/Kaggles/common/utils.py", line 124, in fit
    losses.append(loss.cpu().detach().numpy())
RuntimeError: CUDA error: device-side assert triggered
CUDA kernel errors might be asynchronously reported at some other API call,so the stacktrace below might be incorrect.
For debugging consider passing CUDA_LAUNCH_BLOCKING=1.